[2024-01-08T19:04:07.405+0300] {taskinstance.py:1957} INFO - Dependencies all met for dep_context=non-requeueable deps ti=<TaskInstance: youtube_comments_score.get_data scheduled__2023-02-10T00:00:00+00:00 [queued]>
[2024-01-08T19:04:07.424+0300] {taskinstance.py:1957} INFO - Dependencies all met for dep_context=requeueable deps ti=<TaskInstance: youtube_comments_score.get_data scheduled__2023-02-10T00:00:00+00:00 [queued]>
[2024-01-08T19:04:07.425+0300] {taskinstance.py:2171} INFO - Starting attempt 2 of 2
[2024-01-08T19:04:07.474+0300] {taskinstance.py:2192} INFO - Executing <Task(BashOperator): get_data> on 2023-02-10 00:00:00+00:00
[2024-01-08T19:04:07.500+0300] {standard_task_runner.py:60} INFO - Started process 28587 to run task
[2024-01-08T19:04:07.536+0300] {standard_task_runner.py:87} INFO - Running: ['airflow', 'tasks', 'run', 'youtube_comments_score', 'get_data', 'scheduled__2023-02-10T00:00:00+00:00', '--job-id', '1627', '--raw', '--subdir', 'DAGS_FOLDER/youtube_comments_score.py', '--cfg-path', '/tmp/tmph96u2w4b']
[2024-01-08T19:04:07.541+0300] {standard_task_runner.py:88} INFO - Job 1627: Subtask get_data
[2024-01-08T19:04:07.806+0300] {task_command.py:423} INFO - Running <TaskInstance: youtube_comments_score.get_data scheduled__2023-02-10T00:00:00+00:00 [running]> on host airflow
[2024-01-08T19:04:08.227+0300] {taskinstance.py:2481} INFO - Exporting env vars: AIRFLOW_CTX_DAG_OWNER='admin' AIRFLOW_CTX_DAG_ID='youtube_comments_score' AIRFLOW_CTX_TASK_ID='get_data' AIRFLOW_CTX_EXECUTION_DATE='2023-02-10T00:00:00+00:00' AIRFLOW_CTX_TRY_NUMBER='2' AIRFLOW_CTX_DAG_RUN_ID='scheduled__2023-02-10T00:00:00+00:00'
[2024-01-08T19:04:08.244+0300] {subprocess.py:63} INFO - Tmp dir root location: /tmp
[2024-01-08T19:04:08.246+0300] {subprocess.py:75} INFO - Running command: ['/usr/bin/bash', '-c', 'python3 /home/angry/mlops_3/scripts/get_data.py']
[2024-01-08T19:04:08.289+0300] {subprocess.py:86} INFO - Output:
[2024-01-08T19:04:10.030+0300] {subprocess.py:93} INFO - Traceback (most recent call last):
[2024-01-08T19:04:10.032+0300] {subprocess.py:93} INFO -   File "/home/angry/mlops_3/scripts/get_data.py", line 9, in <module>
[2024-01-08T19:04:10.032+0300] {subprocess.py:93} INFO -     video = api.search_by_keywords(q=query, search_type=["video"], count=10, limit=30)
[2024-01-08T19:04:10.033+0300] {subprocess.py:93} INFO -   File "/home/angry/.local/lib/python3.10/site-packages/pyyoutube/api.py", line 1750, in search_by_keywords
[2024-01-08T19:04:10.033+0300] {subprocess.py:93} INFO -     return self.search(
[2024-01-08T19:04:10.034+0300] {subprocess.py:93} INFO -   File "/home/angry/.local/lib/python3.10/site-packages/pyyoutube/api.py", line 1683, in search
[2024-01-08T19:04:10.034+0300] {subprocess.py:93} INFO -     res_data = self.paged_by_page_token(resource="search", args=args, count=count)
[2024-01-08T19:04:10.035+0300] {subprocess.py:93} INFO -   File "/home/angry/.local/lib/python3.10/site-packages/pyyoutube/api.py", line 487, in paged_by_page_token
[2024-01-08T19:04:10.036+0300] {subprocess.py:93} INFO -     data = self._parse_response(resp)  # origin response
[2024-01-08T19:04:10.036+0300] {subprocess.py:93} INFO -   File "/home/angry/.local/lib/python3.10/site-packages/pyyoutube/api.py", line 327, in _parse_response
[2024-01-08T19:04:10.037+0300] {subprocess.py:93} INFO -     raise PyYouTubeException(response)
[2024-01-08T19:04:10.074+0300] {subprocess.py:93} INFO - pyyoutube.error.PyYouTubeException: YouTubeException(status_code=403,message=The request cannot be completed because you have exceeded your <a href="/youtube/v3/getting-started#quota">quota</a>.)
[2024-01-08T19:04:10.176+0300] {subprocess.py:97} INFO - Command exited with return code 1
[2024-01-08T19:04:10.276+0300] {taskinstance.py:2699} ERROR - Task failed with exception
Traceback (most recent call last):
  File "/usr/local/lib/python3.10/dist-packages/airflow/models/taskinstance.py", line 433, in _execute_task
    result = execute_callable(context=context, **execute_callable_kwargs)
  File "/usr/local/lib/python3.10/dist-packages/airflow/operators/bash.py", line 212, in execute
    raise AirflowException(
airflow.exceptions.AirflowException: Bash command failed. The command returned a non-zero exit code 1.
[2024-01-08T19:04:10.297+0300] {taskinstance.py:1138} INFO - Marking task as FAILED. dag_id=youtube_comments_score, task_id=get_data, execution_date=20230210T000000, start_date=20240108T160407, end_date=20240108T160410
[2024-01-08T19:04:10.357+0300] {standard_task_runner.py:107} ERROR - Failed to execute job 1627 for task get_data (Bash command failed. The command returned a non-zero exit code 1.; 28587)
[2024-01-08T19:04:10.402+0300] {local_task_job_runner.py:234} INFO - Task exited with return code 1
[2024-01-08T19:04:11.180+0300] {taskinstance.py:3281} INFO - 0 downstream tasks scheduled from follow-on schedule check
