[2024-01-08T18:54:29.259+0300] {taskinstance.py:1957} INFO - Dependencies all met for dep_context=non-requeueable deps ti=<TaskInstance: youtube_comments_score.get_data scheduled__2023-01-18T00:00:00+00:00 [queued]>
[2024-01-08T18:54:29.417+0300] {taskinstance.py:1957} INFO - Dependencies all met for dep_context=requeueable deps ti=<TaskInstance: youtube_comments_score.get_data scheduled__2023-01-18T00:00:00+00:00 [queued]>
[2024-01-08T18:54:29.418+0300] {taskinstance.py:2171} INFO - Starting attempt 2 of 2
[2024-01-08T18:54:31.835+0300] {taskinstance.py:2192} INFO - Executing <Task(BashOperator): get_data> on 2023-01-18 00:00:00+00:00
[2024-01-08T18:54:31.950+0300] {standard_task_runner.py:60} INFO - Started process 21932 to run task
[2024-01-08T18:54:32.003+0300] {standard_task_runner.py:87} INFO - Running: ['airflow', 'tasks', 'run', 'youtube_comments_score', 'get_data', 'scheduled__2023-01-18T00:00:00+00:00', '--job-id', '1578', '--raw', '--subdir', 'DAGS_FOLDER/youtube_comments_score.py', '--cfg-path', '/tmp/tmp4sitmqmj']
[2024-01-08T18:54:32.085+0300] {standard_task_runner.py:88} INFO - Job 1578: Subtask get_data
[2024-01-08T18:54:32.976+0300] {task_command.py:423} INFO - Running <TaskInstance: youtube_comments_score.get_data scheduled__2023-01-18T00:00:00+00:00 [running]> on host airflow
[2024-01-08T18:54:33.962+0300] {taskinstance.py:2481} INFO - Exporting env vars: AIRFLOW_CTX_DAG_OWNER='admin' AIRFLOW_CTX_DAG_ID='youtube_comments_score' AIRFLOW_CTX_TASK_ID='get_data' AIRFLOW_CTX_EXECUTION_DATE='2023-01-18T00:00:00+00:00' AIRFLOW_CTX_TRY_NUMBER='2' AIRFLOW_CTX_DAG_RUN_ID='scheduled__2023-01-18T00:00:00+00:00'
[2024-01-08T18:54:33.968+0300] {subprocess.py:63} INFO - Tmp dir root location: /tmp
[2024-01-08T18:54:33.988+0300] {subprocess.py:75} INFO - Running command: ['/usr/bin/bash', '-c', 'python3 /home/angry/mlops_3/scripts/get_data.py']
[2024-01-08T18:54:34.083+0300] {subprocess.py:86} INFO - Output:
[2024-01-08T18:54:36.153+0300] {subprocess.py:93} INFO - Traceback (most recent call last):
[2024-01-08T18:54:36.154+0300] {subprocess.py:93} INFO -   File "/home/angry/mlops_3/scripts/get_data.py", line 9, in <module>
[2024-01-08T18:54:36.155+0300] {subprocess.py:93} INFO -     video = api.search_by_keywords(q=query, search_type=["video"], count=10, limit=30)
[2024-01-08T18:54:36.156+0300] {subprocess.py:93} INFO -   File "/home/angry/.local/lib/python3.10/site-packages/pyyoutube/api.py", line 1750, in search_by_keywords
[2024-01-08T18:54:36.156+0300] {subprocess.py:93} INFO -     return self.search(
[2024-01-08T18:54:36.157+0300] {subprocess.py:93} INFO -   File "/home/angry/.local/lib/python3.10/site-packages/pyyoutube/api.py", line 1683, in search
[2024-01-08T18:54:36.158+0300] {subprocess.py:93} INFO -     res_data = self.paged_by_page_token(resource="search", args=args, count=count)
[2024-01-08T18:54:36.158+0300] {subprocess.py:93} INFO -   File "/home/angry/.local/lib/python3.10/site-packages/pyyoutube/api.py", line 487, in paged_by_page_token
[2024-01-08T18:54:36.158+0300] {subprocess.py:93} INFO -     data = self._parse_response(resp)  # origin response
[2024-01-08T18:54:36.159+0300] {subprocess.py:93} INFO -   File "/home/angry/.local/lib/python3.10/site-packages/pyyoutube/api.py", line 327, in _parse_response
[2024-01-08T18:54:36.159+0300] {subprocess.py:93} INFO -     raise PyYouTubeException(response)
[2024-01-08T18:54:36.160+0300] {subprocess.py:93} INFO - pyyoutube.error.PyYouTubeException: YouTubeException(status_code=403,message=The request cannot be completed because you have exceeded your <a href="/youtube/v3/getting-started#quota">quota</a>.)
[2024-01-08T18:54:36.336+0300] {subprocess.py:97} INFO - Command exited with return code 1
[2024-01-08T18:54:36.616+0300] {taskinstance.py:2699} ERROR - Task failed with exception
Traceback (most recent call last):
  File "/usr/local/lib/python3.10/dist-packages/airflow/models/taskinstance.py", line 433, in _execute_task
    result = execute_callable(context=context, **execute_callable_kwargs)
  File "/usr/local/lib/python3.10/dist-packages/airflow/operators/bash.py", line 212, in execute
    raise AirflowException(
airflow.exceptions.AirflowException: Bash command failed. The command returned a non-zero exit code 1.
[2024-01-08T18:54:36.671+0300] {taskinstance.py:1138} INFO - Marking task as FAILED. dag_id=youtube_comments_score, task_id=get_data, execution_date=20230118T000000, start_date=20240108T155429, end_date=20240108T155436
[2024-01-08T18:54:36.785+0300] {standard_task_runner.py:107} ERROR - Failed to execute job 1578 for task get_data (Bash command failed. The command returned a non-zero exit code 1.; 21932)
[2024-01-08T18:54:36.982+0300] {local_task_job_runner.py:234} INFO - Task exited with return code 1
[2024-01-08T18:54:39.860+0300] {taskinstance.py:3281} INFO - 0 downstream tasks scheduled from follow-on schedule check
