[2024-01-08T19:11:37.924+0300] {taskinstance.py:1957} INFO - Dependencies all met for dep_context=non-requeueable deps ti=<TaskInstance: youtube_comments_score.get_data scheduled__2023-03-16T00:00:00+00:00 [queued]>
[2024-01-08T19:11:38.081+0300] {taskinstance.py:1957} INFO - Dependencies all met for dep_context=requeueable deps ti=<TaskInstance: youtube_comments_score.get_data scheduled__2023-03-16T00:00:00+00:00 [queued]>
[2024-01-08T19:11:38.081+0300] {taskinstance.py:2171} INFO - Starting attempt 1 of 2
[2024-01-08T19:11:39.770+0300] {taskinstance.py:2192} INFO - Executing <Task(BashOperator): get_data> on 2023-03-16 00:00:00+00:00
[2024-01-08T19:11:39.857+0300] {standard_task_runner.py:60} INFO - Started process 33466 to run task
[2024-01-08T19:11:39.910+0300] {standard_task_runner.py:87} INFO - Running: ['airflow', 'tasks', 'run', 'youtube_comments_score', 'get_data', 'scheduled__2023-03-16T00:00:00+00:00', '--job-id', '1667', '--raw', '--subdir', 'DAGS_FOLDER/youtube_comments_score.py', '--cfg-path', '/tmp/tmpgbc1zlzo']
[2024-01-08T19:11:39.984+0300] {standard_task_runner.py:88} INFO - Job 1667: Subtask get_data
[2024-01-08T19:11:41.602+0300] {task_command.py:423} INFO - Running <TaskInstance: youtube_comments_score.get_data scheduled__2023-03-16T00:00:00+00:00 [running]> on host airflow
[2024-01-08T19:11:43.840+0300] {taskinstance.py:2481} INFO - Exporting env vars: AIRFLOW_CTX_DAG_OWNER='admin' AIRFLOW_CTX_DAG_ID='youtube_comments_score' AIRFLOW_CTX_TASK_ID='get_data' AIRFLOW_CTX_EXECUTION_DATE='2023-03-16T00:00:00+00:00' AIRFLOW_CTX_TRY_NUMBER='1' AIRFLOW_CTX_DAG_RUN_ID='scheduled__2023-03-16T00:00:00+00:00'
[2024-01-08T19:11:43.858+0300] {subprocess.py:63} INFO - Tmp dir root location: /tmp
[2024-01-08T19:11:43.860+0300] {subprocess.py:75} INFO - Running command: ['/usr/bin/bash', '-c', 'python3 /home/angry/mlops_3/scripts/get_data.py']
[2024-01-08T19:11:44.060+0300] {subprocess.py:86} INFO - Output:
[2024-01-08T19:11:45.994+0300] {subprocess.py:93} INFO - Traceback (most recent call last):
[2024-01-08T19:11:46.029+0300] {subprocess.py:93} INFO -   File "/home/angry/mlops_3/scripts/get_data.py", line 9, in <module>
[2024-01-08T19:11:46.030+0300] {subprocess.py:93} INFO -     video = api.search_by_keywords(q=query, search_type=["video"], count=10, limit=30)
[2024-01-08T19:11:46.030+0300] {subprocess.py:93} INFO -   File "/home/angry/.local/lib/python3.10/site-packages/pyyoutube/api.py", line 1750, in search_by_keywords
[2024-01-08T19:11:46.031+0300] {subprocess.py:93} INFO -     return self.search(
[2024-01-08T19:11:46.031+0300] {subprocess.py:93} INFO -   File "/home/angry/.local/lib/python3.10/site-packages/pyyoutube/api.py", line 1683, in search
[2024-01-08T19:11:46.031+0300] {subprocess.py:93} INFO -     res_data = self.paged_by_page_token(resource="search", args=args, count=count)
[2024-01-08T19:11:46.032+0300] {subprocess.py:93} INFO -   File "/home/angry/.local/lib/python3.10/site-packages/pyyoutube/api.py", line 487, in paged_by_page_token
[2024-01-08T19:11:46.032+0300] {subprocess.py:93} INFO -     data = self._parse_response(resp)  # origin response
[2024-01-08T19:11:46.032+0300] {subprocess.py:93} INFO -   File "/home/angry/.local/lib/python3.10/site-packages/pyyoutube/api.py", line 327, in _parse_response
[2024-01-08T19:11:46.041+0300] {subprocess.py:93} INFO -     raise PyYouTubeException(response)
[2024-01-08T19:11:46.042+0300] {subprocess.py:93} INFO - pyyoutube.error.PyYouTubeException: YouTubeException(status_code=403,message=The request cannot be completed because you have exceeded your <a href="/youtube/v3/getting-started#quota">quota</a>.)
[2024-01-08T19:11:46.187+0300] {subprocess.py:97} INFO - Command exited with return code 1
[2024-01-08T19:11:46.325+0300] {taskinstance.py:2699} ERROR - Task failed with exception
Traceback (most recent call last):
  File "/usr/local/lib/python3.10/dist-packages/airflow/models/taskinstance.py", line 433, in _execute_task
    result = execute_callable(context=context, **execute_callable_kwargs)
  File "/usr/local/lib/python3.10/dist-packages/airflow/operators/bash.py", line 212, in execute
    raise AirflowException(
airflow.exceptions.AirflowException: Bash command failed. The command returned a non-zero exit code 1.
[2024-01-08T19:11:46.378+0300] {taskinstance.py:1138} INFO - Marking task as UP_FOR_RETRY. dag_id=youtube_comments_score, task_id=get_data, execution_date=20230316T000000, start_date=20240108T161137, end_date=20240108T161146
[2024-01-08T19:11:47.215+0300] {standard_task_runner.py:107} ERROR - Failed to execute job 1667 for task get_data (Bash command failed. The command returned a non-zero exit code 1.; 33466)
[2024-01-08T19:11:47.443+0300] {local_task_job_runner.py:234} INFO - Task exited with return code 1
[2024-01-08T19:11:48.089+0300] {taskinstance.py:3281} INFO - 0 downstream tasks scheduled from follow-on schedule check
