[2024-01-08T18:59:56.549+0300] {taskinstance.py:1957} INFO - Dependencies all met for dep_context=non-requeueable deps ti=<TaskInstance: youtube_comments_score.get_data scheduled__2023-02-01T00:00:00+00:00 [queued]>
[2024-01-08T18:59:56.570+0300] {taskinstance.py:1957} INFO - Dependencies all met for dep_context=requeueable deps ti=<TaskInstance: youtube_comments_score.get_data scheduled__2023-02-01T00:00:00+00:00 [queued]>
[2024-01-08T18:59:56.571+0300] {taskinstance.py:2171} INFO - Starting attempt 2 of 2
[2024-01-08T18:59:56.603+0300] {taskinstance.py:2192} INFO - Executing <Task(BashOperator): get_data> on 2023-02-01 00:00:00+00:00
[2024-01-08T18:59:56.615+0300] {standard_task_runner.py:60} INFO - Started process 25693 to run task
[2024-01-08T18:59:56.635+0300] {standard_task_runner.py:87} INFO - Running: ['airflow', 'tasks', 'run', 'youtube_comments_score', 'get_data', 'scheduled__2023-02-01T00:00:00+00:00', '--job-id', '1608', '--raw', '--subdir', 'DAGS_FOLDER/youtube_comments_score.py', '--cfg-path', '/tmp/tmp8qe7a8si']
[2024-01-08T18:59:56.640+0300] {standard_task_runner.py:88} INFO - Job 1608: Subtask get_data
[2024-01-08T18:59:57.093+0300] {task_command.py:423} INFO - Running <TaskInstance: youtube_comments_score.get_data scheduled__2023-02-01T00:00:00+00:00 [running]> on host airflow
[2024-01-08T18:59:57.678+0300] {taskinstance.py:2481} INFO - Exporting env vars: AIRFLOW_CTX_DAG_OWNER='admin' AIRFLOW_CTX_DAG_ID='youtube_comments_score' AIRFLOW_CTX_TASK_ID='get_data' AIRFLOW_CTX_EXECUTION_DATE='2023-02-01T00:00:00+00:00' AIRFLOW_CTX_TRY_NUMBER='2' AIRFLOW_CTX_DAG_RUN_ID='scheduled__2023-02-01T00:00:00+00:00'
[2024-01-08T18:59:57.684+0300] {subprocess.py:63} INFO - Tmp dir root location: /tmp
[2024-01-08T18:59:57.686+0300] {subprocess.py:75} INFO - Running command: ['/usr/bin/bash', '-c', 'python3 /home/angry/mlops_3/scripts/get_data.py']
[2024-01-08T18:59:57.714+0300] {subprocess.py:86} INFO - Output:
[2024-01-08T18:59:58.916+0300] {subprocess.py:93} INFO - Traceback (most recent call last):
[2024-01-08T18:59:58.917+0300] {subprocess.py:93} INFO -   File "/home/angry/mlops_3/scripts/get_data.py", line 9, in <module>
[2024-01-08T18:59:58.917+0300] {subprocess.py:93} INFO -     video = api.search_by_keywords(q=query, search_type=["video"], count=10, limit=30)
[2024-01-08T18:59:58.917+0300] {subprocess.py:93} INFO -   File "/home/angry/.local/lib/python3.10/site-packages/pyyoutube/api.py", line 1750, in search_by_keywords
[2024-01-08T18:59:58.918+0300] {subprocess.py:93} INFO -     return self.search(
[2024-01-08T18:59:58.918+0300] {subprocess.py:93} INFO -   File "/home/angry/.local/lib/python3.10/site-packages/pyyoutube/api.py", line 1683, in search
[2024-01-08T18:59:58.918+0300] {subprocess.py:93} INFO -     res_data = self.paged_by_page_token(resource="search", args=args, count=count)
[2024-01-08T18:59:58.919+0300] {subprocess.py:93} INFO -   File "/home/angry/.local/lib/python3.10/site-packages/pyyoutube/api.py", line 487, in paged_by_page_token
[2024-01-08T18:59:58.919+0300] {subprocess.py:93} INFO -     data = self._parse_response(resp)  # origin response
[2024-01-08T18:59:58.920+0300] {subprocess.py:93} INFO -   File "/home/angry/.local/lib/python3.10/site-packages/pyyoutube/api.py", line 327, in _parse_response
[2024-01-08T18:59:58.920+0300] {subprocess.py:93} INFO -     raise PyYouTubeException(response)
[2024-01-08T18:59:58.921+0300] {subprocess.py:93} INFO - pyyoutube.error.PyYouTubeException: YouTubeException(status_code=403,message=The request cannot be completed because you have exceeded your <a href="/youtube/v3/getting-started#quota">quota</a>.)
[2024-01-08T18:59:59.007+0300] {subprocess.py:97} INFO - Command exited with return code 1
[2024-01-08T18:59:59.074+0300] {taskinstance.py:2699} ERROR - Task failed with exception
Traceback (most recent call last):
  File "/usr/local/lib/python3.10/dist-packages/airflow/models/taskinstance.py", line 433, in _execute_task
    result = execute_callable(context=context, **execute_callable_kwargs)
  File "/usr/local/lib/python3.10/dist-packages/airflow/operators/bash.py", line 212, in execute
    raise AirflowException(
airflow.exceptions.AirflowException: Bash command failed. The command returned a non-zero exit code 1.
[2024-01-08T18:59:59.085+0300] {taskinstance.py:1138} INFO - Marking task as FAILED. dag_id=youtube_comments_score, task_id=get_data, execution_date=20230201T000000, start_date=20240108T155956, end_date=20240108T155959
[2024-01-08T18:59:59.136+0300] {standard_task_runner.py:107} ERROR - Failed to execute job 1608 for task get_data (Bash command failed. The command returned a non-zero exit code 1.; 25693)
[2024-01-08T18:59:59.195+0300] {local_task_job_runner.py:234} INFO - Task exited with return code 1
[2024-01-08T18:59:59.287+0300] {taskinstance.py:3281} INFO - 0 downstream tasks scheduled from follow-on schedule check
